<?xml version="1.0" encoding="utf-8"?>
<!-- =================================================================================== -->
<!-- |    This document was autogenerated by xacro from model.xacro                    | -->
<!-- |    EDITING THIS FILE BY HAND IS NOT RECOMMENDED                                 | -->
<!-- =================================================================================== -->
<robot name="zb320">
    <material name="silver">
        <color rgba="0.700 0.700 0.700 1.000"/>
    </material>
    <material name="red">
        <color rgba="1.000 0.000 0.000 0.700"/>
    </material>
    <material name="green">
        <color rgba="0.000 1.000 0.000 0.700"/>
    </material>
    <material name="blue">
        <color rgba="0.000 0.000 1.000 0.700"/>
    </material>
    <material name="white">
        <color rgba="1.000 1.000 1.000 0.700"/>
    </material>

    <transmission name="Rev5_tran">
        <type>transmission_interface/SimpleTransmission</type>
        <joint name="Rev5">
            <hardwareInterface>hardware_interface/EffortJointInterface</hardwareInterface>
        </joint>
        <actuator name="Rev5_actr">
            <hardwareInterface>hardware_interface/EffortJointInterface</hardwareInterface>
            <mechanicalReduction>1</mechanicalReduction>
        </actuator>
    </transmission>

    <transmission name="Rev6_tran">
        <type>transmission_interface/SimpleTransmission</type>
        <joint name="Rev6">
            <hardwareInterface>hardware_interface/EffortJointInterface</hardwareInterface>
        </joint>
        <actuator name="Rev6_actr">
            <hardwareInterface>hardware_interface/EffortJointInterface</hardwareInterface>
            <mechanicalReduction>1</mechanicalReduction>
        </actuator>
    </transmission>

    <transmission name="Rev7_tran">
        <type>transmission_interface/SimpleTransmission</type>
        <joint name="Rev7">
            <hardwareInterface>hardware_interface/EffortJointInterface</hardwareInterface>
        </joint>
        <actuator name="Rev7_actr">
            <hardwareInterface>hardware_interface/EffortJointInterface</hardwareInterface>
            <mechanicalReduction>1</mechanicalReduction>
        </actuator>
    </transmission>

    <transmission name="Rev8_tran">
        <type>transmission_interface/SimpleTransmission</type>
        <joint name="Rev8">
            <hardwareInterface>hardware_interface/EffortJointInterface</hardwareInterface>
        </joint>
        <actuator name="Rev8_actr">
            <hardwareInterface>hardware_interface/EffortJointInterface</hardwareInterface>
            <mechanicalReduction>1</mechanicalReduction>
        </actuator>
    </transmission>

    <gazebo>
        <plugin filename="libgazebo_ros_control.so" name="control"/>
    </gazebo>

    <gazebo reference="base_link">
        <material>Gazebo/Silver</material>
        <mu1>0.2</mu1>
        <mu2>0.2</mu2>
        <selfCollide>true</selfCollide>
        <gravity>true</gravity>
    </gazebo>

    <gazebo reference="link_1_1">
        <material>Gazebo/Silver</material>
        <mu1>0.2</mu1>
        <mu2>0.2</mu2>
        <selfCollide>true</selfCollide>
    </gazebo>

    <gazebo reference="link_2_1">
        <material>Gazebo/Silver</material>
        <mu1>0.2</mu1>
        <mu2>0.2</mu2>
        <selfCollide>true</selfCollide>
    </gazebo>

    <gazebo reference="link_3_1">
        <material>Gazebo/Silver</material>
        <mu1>0.2</mu1>
        <mu2>0.2</mu2>
        <selfCollide>true</selfCollide>
    </gazebo>

    <gazebo reference="link_4_1">
        <material>Gazebo/Silver</material>
        <mu1>0.2</mu1>
        <mu2>0.2</mu2>
        <selfCollide>true</selfCollide>
    </gazebo>

    <link name="base_link">
        <inertial>
            <origin rpy="0 0 0" xyz="0.0 0.0 0.0"/>
            <mass value="1.4110802987401645"/>
            <inertia ixx="0.001793" ixy="0.0" ixz="0.0" iyy="0.001793" iyz="-0.0" izz="0.003498"/>
        </inertial>
        <visual>
            <origin rpy="0 0 3.14" xyz="0 0 0"/>
            <geometry>
                <mesh filename="package://zb320_description/meshes/base_link.stl" scale="0.001 0.001 0.001"/>
            </geometry>
            <material name="silver"/>
        </visual>
        <collision>
            <origin rpy="0 0 0" xyz="0 0 0"/>
            <geometry>
                <mesh filename="package://zb320_description/meshes/base_link.stl" scale="0.001 0.001 0.001"/>
            </geometry>
        </collision>
    </link>

    <link name="link_1_1">
        <inertial>
            <origin rpy="0 0 0" xyz="0.0 0.0 -0.02"/>
            <mass value="2.152080592427195"/>
            <inertia ixx="0.002479" ixy="-1.4e-05" ixz="0.000171" iyy="0.002425" iyz="-4e-06" izz="0.00328"/>
        </inertial>
        <visual>
            <origin rpy="0 0 3.14" xyz="-0.0 -0.0 -0.02"/>
            <geometry>
                <mesh filename="package://zb320_description/meshes/link_1_1.stl" scale="0.001 0.001 0.001"/>
            </geometry>
            <material name="silver"/>
        </visual>
        <collision>
            <origin rpy="0 0 0" xyz="-0.0 -0.0 -0.02"/>
            <geometry>
                <mesh filename="package://zb320_description/meshes/link_1_1.stl" scale="0.001 0.001 0.001"/>
            </geometry>
        </collision>
    </link>

    <link name="link_2_1">
        <inertial>
            <origin rpy="0 0 0" xyz="0.0 0.0 -0.09"/>
            <mass value="0.48368669197035047"/>
            <inertia ixx="0.001168" ixy="1e-06" ixz="-7e-06" iyy="0.001158" iyz="1.1e-05" izz="5.8e-05"/>
        </inertial>
        <visual>
            <origin rpy="0 0 3.14" xyz="-0.0 -0.0 -0.09"/>
            <geometry>
                <mesh filename="package://zb320_description/meshes/link_2_1.stl" scale="0.001 0.001 0.001"/>
            </geometry>
            <material name="silver"/>
        </visual>
        <collision>
            <origin rpy="0 0 0" xyz="-0.0 -0.0 -0.09"/>
            <geometry>
                <mesh filename="package://zb320_description/meshes/link_2_1.stl" scale="0.001 0.001 0.001"/>
            </geometry>
        </collision>
    </link>

    <link name="link_3_1">
        <inertial>
            <origin rpy="0 0 0" xyz="0.0 0.0 -0.24"/>
            <mass value="0.5032706604395567"/>
            <inertia ixx="0.001721" ixy="-1.1e-05" ixz="1e-06" iyy="5.3e-05" iyz="-3.7e-05" izz="0.001709"/>
        </inertial>
        <visual>
            <origin rpy="0 0 3.14" xyz="0.0 0.0 -0.24"/>
            <geometry>
                <mesh filename="package://zb320_description/meshes/link_3_1.stl" scale="0.001 0.001 0.001"/>
            </geometry>
            <material name="silver"/>
        </visual>
        <collision>
            <origin rpy="0 0 0" xyz="0.0 0.0 -0.24"/>
            <geometry>
                <mesh filename="package://zb320_description/meshes/link_3_1.stl" scale="0.001 0.001 0.001"/>
            </geometry>
        </collision>
    </link>

    <link name="link_4_1">
        <inertial>
            <origin rpy="0 0 0" xyz="0.0 -0.17 -0.24"/>
            <mass value="0.12489833913220899"/>
            <inertia ixx="3.1e-05" ixy="-3e-06" ixz="2e-06" iyy="1.8e-05" iyz="7e-06" izz="2.3e-05"/>
        </inertial>
        <visual>
            <origin rpy="0 0 3.14" xyz="-0.0 -0.17 -0.24"/>
            <geometry>
                <mesh filename="package://zb320_description/meshes/link_4_1.stl" scale="0.001 0.001 0.001"/>
            </geometry>
            <material name="silver"/>
        </visual>
        <collision>
            <origin rpy="0 0 0" xyz="-0.0 -0.17 -0.24"/>
            <geometry>
                <mesh filename="package://zb320_description/meshes/link_4_1.stl" scale="0.001 0.001 0.001"/>
            </geometry>
        </collision>
    </link>

    <joint name="Rev5" type="continuous">
        <origin rpy="0 0 0" xyz="0.0 0.0 0.02"/>
        <parent link="base_link"/>
        <child link="link_1_1"/>
        <axis xyz="0.0 0.0 1.0"/>
    </joint>

    <joint name="Rev6" type="continuous">
        <origin rpy="0 0 0" xyz="0.0 0.0 0.07"/>
        <parent link="link_1_1"/>
        <child link="link_2_1"/>
        <axis xyz="1.0 0.0 0.0"/>
    </joint>
    
    <joint name="Rev7" type="continuous">
        <origin rpy="0 0 0" xyz="0.0 0.0 0.15"/>
        <parent link="link_2_1"/>
        <child link="link_3_1"/>
        <axis xyz="1.0 0.0 0.0"/>
    </joint>
    
    <joint name="Rev8" type="continuous">
        <origin rpy="0 0 0" xyz="0.0 0.17 0.0"/>
        <parent link="link_3_1"/>
        <child link="link_4_1"/>
        <axis xyz="1.0 0.0 0.0"/>
    </joint>
</robot>
