<?xml version="1.0" ?>
<robot name="zb320" xmlns:xacro="http://www.ros.org/wiki/xacro">

    <xacro:include filename="$(find zb320_description)/urdf/materials.xacro" />
    <xacro:include filename="$(find zb320_description)/urdf/model.trans" />
    <xacro:include filename="$(find zb320_description)/urdf/model.gazebo" />
    
    <link name="base_link">
        <inertial>
            <origin rpy="0 0 0" xyz="0.0 0.0 0.0"/>
            <mass value="1.4110802987401645"/>
            <inertia ixx="0.001793" ixy="0.0" ixz="0.0" iyy="0.001793" iyz="-0.0" izz="0.003498"/>
        </inertial>
        <visual>
            <origin rpy="0 0 3.14" xyz="0 0 0"/>
            <geometry>
                <mesh filename="package://zb320_description/meshes/base_link.stl" scale="0.001 0.001 0.001"/>
            </geometry>
            <material name="silver"/>
        </visual>
        <collision>
            <origin rpy="0 0 0" xyz="0 0 0"/>
            <geometry>
                <mesh filename="package://zb320_description/meshes/base_link.stl" scale="0.001 0.001 0.001"/>
            </geometry>
        </collision>
    </link>

    <link name="link_1_1">
        <inertial>
            <origin rpy="0 0 0" xyz="0.0 0.0 -0.02"/>
            <mass value="2.152080592427195"/>
            <inertia ixx="0.002479" ixy="-1.4e-05" ixz="0.000171" iyy="0.002425" iyz="-4e-06" izz="0.00328"/>
        </inertial>
        <visual>
            <origin rpy="0 0 3.14" xyz="-0.0 -0.0 -0.02"/>
            <geometry>
                <mesh filename="package://zb320_description/meshes/link_1_1.stl" scale="0.001 0.001 0.001"/>
            </geometry>
            <material name="red"/>
        </visual>
        <collision>
            <origin rpy="0 0 0" xyz="-0.0 -0.0 -0.02"/>
            <geometry>
                <mesh filename="package://zb320_description/meshes/link_1_1.stl" scale="0.001 0.001 0.001"/>
            </geometry>
        </collision>
    </link>

    <link name="link_2_1">
        <inertial>
            <origin rpy="0 0 0" xyz="0.0 0.0 -0.09"/>
            <mass value="0.48368669197035047"/>
            <inertia ixx="0.001168" ixy="1e-06" ixz="-7e-06" iyy="0.001158" iyz="1.1e-05" izz="5.8e-05"/>
        </inertial>
        <visual>
            <origin rpy="0 0 3.14" xyz="-0.0 -0.0 -0.09"/>
            <geometry>
                <mesh filename="package://zb320_description/meshes/link_2_1.stl" scale="0.001 0.001 0.001"/>
            </geometry>
            <material name="green"/>
        </visual>
        <collision>
            <origin rpy="0 0 0" xyz="-0.0 -0.0 -0.09"/>
            <geometry>
                <mesh filename="package://zb320_description/meshes/link_2_1.stl" scale="0.001 0.001 0.001"/>
            </geometry>
        </collision>
    </link>

    <link name="link_3_1">
        <inertial>
            <origin rpy="0 0 0" xyz="0.0 0.0 -0.24"/>
            <mass value="0.5032706604395567"/>
            <inertia ixx="0.001721" ixy="-1.1e-05" ixz="1e-06" iyy="5.3e-05" iyz="-3.7e-05" izz="0.001709"/>
        </inertial>
        <visual>
            <origin rpy="0 0 3.14" xyz="0.0 0.0 -0.24"/>
            <geometry>
                <mesh filename="package://zb320_description/meshes/link_3_1.stl" scale="0.001 0.001 0.001"/>
            </geometry>
            <material name="blue"/>
        </visual>
        <collision>
            <origin rpy="0 0 0" xyz="0.0 0.0 -0.24"/>
            <geometry>
                <mesh filename="package://zb320_description/meshes/link_3_1.stl" scale="0.001 0.001 0.001"/>
            </geometry>
        </collision>
    </link>

    <link name="link_4_1">
        <inertial>
            <origin rpy="0 0 0" xyz="0.0 -0.17 -0.24"/>
            <mass value="0.12489833913220899"/>
            <inertia ixx="3.1e-05" ixy="-3e-06" ixz="2e-06" iyy="1.8e-05" iyz="7e-06" izz="2.3e-05"/>
        </inertial>
        <visual>
            <origin rpy="0 0 3.14" xyz="-0.0 -0.17 -0.24"/>
            <geometry>
                <mesh filename="package://zb320_description/meshes/link_4_1.stl" scale="0.001 0.001 0.001"/>
            </geometry>
            <material name="white"/>
        </visual>
        <collision>
            <origin rpy="0 0 0" xyz="-0.0 -0.17 -0.24"/>
            <geometry>
                <mesh filename="package://zb320_description/meshes/link_4_1.stl" scale="0.001 0.001 0.001"/>
            </geometry>
        </collision>
    </link>

    <joint name="Rev5" type="continuous">
        <origin rpy="0 0 0" xyz="0.0 0.0 0.02"/>
        <parent link="base_link"/>
        <child link="link_1_1"/>
        <axis xyz="0.0 0.0 1.0"/>
    </joint>

    <joint name="Rev6" type="continuous">
        <origin rpy="0 0 0" xyz="0.0 0.0 0.07"/>
        <parent link="link_1_1"/>
        <child link="link_2_1"/>
        <axis xyz="1.0 0.0 0.0"/>
    </joint>

    <joint name="Rev7" type="continuous">
        <origin rpy="0 0 0" xyz="0.0 0.0 0.15"/>
        <parent link="link_2_1"/>
        <child link="link_3_1"/>
        <axis xyz="1.0 0.0 0.0"/>
    </joint>

    <joint name="Rev8" type="continuous">
        <origin rpy="0 0 0" xyz="0.0 0.17 0.0"/>
        <parent link="link_3_1"/>
        <child link="link_4_1"/>
        <axis xyz="1.0 0.0 0.0"/>
    </joint>

</robot>
